<?xml version="1.0" ?>
<!-- =================================================================================== -->
<!-- |    This document was autogenerated by xacro from /home/juptegraph/Workspaces/Robotics/Projects/CORI/cori_ws/src/cori_description/urdf/cori.urdf.xacro | -->
<!-- |    EDITING THIS FILE BY HAND IS NOT RECOMMENDED                                 | -->
<!-- =================================================================================== -->
<robot name="cori">
  <!-- Materials -->
  <material name="body_material">
    <color rgba="0.82 0.81 0.78 1.0"/>
  </material>
  <material name="joint_material">
    <color rgba="0.35 0.35 0.35 1.0"/>
  </material>
  <material name="screen_material">
    <color rgba="0.05 0.05 0.05 1.0"/>
  </material>
  <material name="eye_material">
    <color rgba="1.0 1.0 1.0 1.0"/>
  </material>
  <!-- Base Link -->
  <link name="base_link">
    <inertial>
      <mass value="0.1"/>
      <inertia ixx="0.001" ixy="0.0" ixz="0.0" iyy="0.001" iyz="0.0" izz="0.001"/>
    </inertial>
  </link>
  <!-- Head Assembly -->
  <link name="head">
    <visual>
      <geometry>
        <mesh filename="package://robot_description/meshes/visual/head.dae"/>
      </geometry>
      <material name="body_material"/>
    </visual>
    <collision>
      <geometry>
        <mesh filename="package://robot_description/meshes/collision/head.stl"/>
      </geometry>
    </collision>
    <inertial>
      <mass value="1.5"/>
      <inertia ixx="0.015" ixy="0.0" ixz="0.0" iyy="0.015" iyz="0.0" izz="0.015"/>
    </inertial>
  </link>
  <joint name="neck_joint" type="revolute">
    <parent link="base_link"/>
    <child link="head"/>
    <axis xyz="0 0 1"/>
    <limit effort="100.0" lower="-2.09" upper="2.09" velocity="1.0"/>
    <dynamics damping="0.7" friction="0.9"/>
    <origin rpy="0 0 0" xyz="0 0 0.38"/>
    <default>
      <angle>0.0</angle>
    </default>
  </joint>
  <link name="screen">
    <visual>
      <geometry>
        <mesh filename="package://robot_description/meshes/visual/screen.dae"/>
      </geometry>
      <material name="screen_material"/>
    </visual>
    <collision>
      <geometry>
        <mesh filename="package://robot_description/meshes/collision/screen.stl"/>
      </geometry>
    </collision>
  </link>
  <joint name="screen_joint" type="fixed">
    <parent link="head"/>
    <child link="screen"/>
    <origin rpy="0 0 0" xyz="0 0 0.05"/>
  </joint>
  <link name="left_eye">
    <visual>
      <geometry>
        <sphere radius="0.015"/>
      </geometry>
      <material name="eye_material"/>
      <origin rpy="0 0 0" xyz="-0.08 0 0.07"/>
    </visual>
  </link>
  <joint name="left_eye_joint" type="fixed">
    <parent link="screen"/>
    <child link="left_eye"/>
  </joint>
  <link name="right_eye">
    <visual>
      <geometry>
        <sphere radius="0.015"/>
      </geometry>
      <material name="eye_material"/>
      <origin rpy="0 0 0" xyz="0.08 0 0.07"/>
    </visual>
  </link>
  <joint name="right_eye_joint" type="fixed">
    <parent link="screen"/>
    <child link="right_eye"/>
  </joint>
  <!-- Torso Assembly -->
  <link name="torso">
    <visual>
      <geometry>
        <mesh filename="package://robot_description/meshes/visual/torso.dae"/>
      </geometry>
      <material name="body_material"/>
    </visual>
    <collision>
      <geometry>
        <mesh filename="package://robot_description/meshes/collision/torso.stl"/>
      </geometry>
    </collision>
    <inertial>
      <mass value="8.0"/>
      <inertia ixx="0.08" ixy="0.0" ixz="0.0" iyy="0.08" iyz="0.0" izz="0.08"/>
    </inertial>
  </link>
  <joint name="waist_joint" type="revolute">
    <parent link="base_link"/>
    <child link="torso"/>
    <axis xyz="0 0 1"/>
    <limit effort="100.0" lower="-2.09" upper="2.09" velocity="1.0"/>
    <dynamics damping="0.7" friction="0.9"/>
    <origin rpy="0 0 0" xyz="0 0 0"/>
    <default>
      <angle>0.0</angle>
    </default>
  </joint>
  <!-- Left Arm -->
  <link name="left_arm_upper">
    <visual>
      <geometry>
        <mesh filename="package://robot_description/meshes/visual/arm_upper.dae"/>
      </geometry>
      <material name="body_material"/>
    </visual>
    <collision>
      <geometry>
        <mesh filename="package://robot_description/meshes/collision/arm_upper.stl"/>
      </geometry>
    </collision>
    <inertial>
      <mass value="1.2"/>
      <inertia ixx="0.012" ixy="0.0" ixz="0.0" iyy="0.012" iyz="0.0" izz="0.012"/>
    </inertial>
  </link>
  <joint name="left_shoulder_joint" type="revolute">
    <parent link="torso"/>
    <child link="left_arm_upper"/>
    <axis xyz="0 1 0"/>
    <limit effort="100.0" lower="-2.09" upper="2.09" velocity="1.0"/>
    <dynamics damping="0.7" friction="0.9"/>
    <origin rpy="0 0 0" xyz="-0.16 0 0.38"/>
    <default>
      <angle>0.3</angle>
    </default>
  </joint>
  <link name="left_arm_elbow">
    <visual>
      <geometry>
        <mesh filename="package://robot_description/meshes/visual/elbow.dae"/>
      </geometry>
      <material name="joint_material"/>
    </visual>
    <collision>
      <geometry>
        <mesh filename="package://robot_description/meshes/collision/elbow.stl"/>
      </geometry>
    </collision>
  </link>
  <joint name="left_elbow_joint" type="revolute">
    <parent link="left_arm_upper"/>
    <child link="left_arm_elbow"/>
    <axis xyz="0 1 0"/>
    <limit effort="100.0" lower="-2.09" upper="2.09" velocity="1.0"/>
    <dynamics damping="0.7" friction="0.9"/>
    <origin rpy="0 0 0" xyz="0 0 0.28"/>
    <default>
      <angle>0.2</angle>
    </default>
  </joint>
  <link name="left_arm_forearm">
    <visual>
      <geometry>
        <mesh filename="package://robot_description/meshes/visual/arm_forearm.dae"/>
      </geometry>
      <material name="body_material"/>
    </visual>
    <collision>
      <geometry>
        <mesh filename="package://robot_description/meshes/collision/arm_forearm.stl"/>
      </geometry>
    </collision>
    <inertial>
      <mass value="1.0"/>
      <inertia ixx="0.01" ixy="0.0" ixz="0.0" iyy="0.01" iyz="0.0" izz="0.01"/>
    </inertial>
  </link>
  <joint name="left_wrist_joint" type="revolute">
    <parent link="left_arm_elbow"/>
    <child link="left_arm_forearm"/>
    <axis xyz="0 1 0"/>
    <limit effort="100.0" lower="-2.09" upper="2.09" velocity="1.0"/>
    <dynamics damping="0.7" friction="0.9"/>
    <origin rpy="0 0 0" xyz="0 0 0.04"/>
    <default>
      <angle>0.0</angle>
    </default>
  </joint>
  <link name="left_arm_wrist">
    <visual>
      <geometry>
        <mesh filename="package://robot_description/meshes/visual/wrist.dae"/>
      </geometry>
      <material name="joint_material"/>
    </visual>
    <collision>
      <geometry>
        <mesh filename="package://robot_description/meshes/collision/wrist.stl"/>
      </geometry>
    </collision>
  </link>
  <joint name="left_wrist_end_joint" type="fixed">
    <parent link="left_arm_forearm"/>
    <child link="left_arm_wrist"/>
    <origin rpy="0 0 0" xyz="0 0 0.26"/>
  </joint>
  <link name="left_hand_palm">
    <visual>
      <geometry>
        <mesh filename="package://robot_description/meshes/visual/hand_palm.dae"/>
      </geometry>
      <material name="joint_material"/>
    </visual>
    <collision>
      <geometry>
        <mesh filename="package://robot_description/meshes/collision/hand_palm.stl"/>
      </geometry>
    </collision>
    <inertial>
      <mass value="0.6"/>
      <inertia ixx="0.0015" ixy="0.0" ixz="0.0" iyy="0.0015" iyz="0.0" izz="0.0015"/>
    </inertial>
  </link>
  <joint name="left_wrist_hand_joint" type="fixed">
    <parent link="left_arm_wrist"/>
    <child link="left_hand_palm"/>
    <origin rpy="0 0 0" xyz="0 0 0"/>
  </joint>
  <link name="left_finger_1">
    <visual>
      <geometry>
        <mesh filename="package://robot_description/meshes/visual/finger.dae"/>
      </geometry>
      <material name="joint_material"/>
    </visual>
    <collision>
      <geometry>
        <mesh filename="package://robot_description/meshes/collision/finger.stl"/>
      </geometry>
    </collision>
    <inertial>
      <mass value="0.1"/>
      <inertia ixx="0.0001" ixy="0.0" ixz="0.0" iyy="0.0001" iyz="0.0" izz="0.0001"/>
    </inertial>
  </link>
  <joint name="left_finger_1_joint" type="revolute">
    <parent link="left_hand_palm"/>
    <child link="left_finger_1"/>
    <axis xyz="0 0 1"/>
    <limit effort="50.0" lower="0.0" upper="1.57" velocity="0.5"/>
    <dynamics damping="0.5" friction="0.7"/>
    <origin rpy="0 0 0" xyz="-0.02 0 -0.025"/>
    <default>
      <angle>0.0</angle>
    </default>
  </joint>
  <link name="left_finger_2">
    <visual>
      <geometry>
        <mesh filename="package://robot_description/meshes/visual/finger.dae"/>
      </geometry>
      <material name="joint_material"/>
    </visual>
    <collision>
      <geometry>
        <mesh filename="package://robot_description/meshes/collision/finger.stl"/>
      </geometry>
    </collision>
    <inertial>
      <mass value="0.1"/>
      <inertia ixx="0.0001" ixy="0.0" ixz="0.0" iyy="0.0001" iyz="0.0" izz="0.0001"/>
    </inertial>
  </link>
  <joint name="left_finger_2_joint" type="revolute">
    <parent link="left_hand_palm"/>
    <child link="left_finger_2"/>
    <axis xyz="0 0 1"/>
    <limit effort="50.0" lower="0.0" upper="1.57" velocity="0.5"/>
    <dynamics damping="0.5" friction="0.7"/>
    <origin rpy="0 0 0" xyz="-0.0067 0 -0.025"/>
    <default>
      <angle>0.0</angle>
    </default>
  </joint>
  <link name="left_finger_3">
    <visual>
      <geometry>
        <mesh filename="package://robot_description/meshes/visual/finger.dae"/>
      </geometry>
      <material name="joint_material"/>
    </visual>
    <collision>
      <geometry>
        <mesh filename="package://robot_description/meshes/collision/finger.stl"/>
      </geometry>
    </collision>
    <inertial>
      <mass value="0.1"/>
      <inertia ixx="0.0001" ixy="0.0" ixz="0.0" iyy="0.0001" iyz="0.0" izz="0.0001"/>
    </inertial>
  </link>
  <joint name="left_finger_3_joint" type="revolute">
    <parent link="left_hand_palm"/>
    <child link="left_finger_3"/>
    <axis xyz="0 0 1"/>
    <limit effort="50.0" lower="0.0" upper="1.57" velocity="0.5"/>
    <dynamics damping="0.5" friction="0.7"/>
    <origin rpy="0 0 0" xyz="0.0067 0 -0.025"/>
    <default>
      <angle>0.0</angle>
    </default>
  </joint>
  <link name="left_finger_4">
    <visual>
      <geometry>
        <mesh filename="package://robot_description/meshes/visual/finger.dae"/>
      </geometry>
      <material name="joint_material"/>
    </visual>
    <collision>
      <geometry>
        <mesh filename="package://robot_description/meshes/collision/finger.stl"/>
      </geometry>
    </collision>
    <inertial>
      <mass value="0.1"/>
      <inertia ixx="0.0001" ixy="0.0" ixz="0.0" iyy="0.0001" iyz="0.0" izz="0.0001"/>
    </inertial>
  </link>
  <joint name="left_finger_4_joint" type="revolute">
    <parent link="left_hand_palm"/>
    <child link="left_finger_4"/>
    <axis xyz="0 0 1"/>
    <limit effort="50.0" lower="0.0" upper="1.57" velocity="0.5"/>
    <dynamics damping="0.5" friction="0.7"/>
    <origin rpy="0 0 0" xyz="0.02 0 -0.025"/>
    <default>
      <angle>0.0</angle>
    </default>
  </joint>
  <!-- Right Arm (Mirrored) -->
  <link name="right_arm_upper">
    <visual>
      <geometry>
        <mesh filename="package://robot_description/meshes/visual/arm_upper.dae"/>
      </geometry>
      <material name="body_material"/>
    </visual>
    <collision>
      <geometry>
        <mesh filename="package://robot_description/meshes/collision/arm_upper.stl"/>
      </geometry>
    </collision>
    <inertial>
      <mass value="1.2"/>
      <inertia ixx="0.012" ixy="0.0" ixz="0.0" iyy="0.012" iyz="0.0" izz="0.012"/>
    </inertial>
  </link>
  <joint name="right_shoulder_joint" type="revolute">
    <parent link="torso"/>
    <child link="right_arm_upper"/>
    <axis xyz="0 1 0"/>
    <limit effort="100.0" lower="-2.09" upper="2.09" velocity="1.0"/>
    <dynamics damping="0.7" friction="0.9"/>
    <origin rpy="0 0 0" xyz="0.16 0 0.38"/>
    <default>
      <angle>0.3</angle>
    </default>
  </joint>
  <link name="right_arm_elbow">
    <visual>
      <geometry>
        <mesh filename="package://robot_description/meshes/visual/elbow.dae"/>
      </geometry>
      <material name="joint_material"/>
    </visual>
    <collision>
      <geometry>
        <mesh filename="package://robot_description/meshes/collision/elbow.stl"/>
      </geometry>
    </collision>
  </link>
  <joint name="right_elbow_joint" type="revolute">
    <parent link="right_arm_upper"/>
    <child link="right_arm_elbow"/>
    <axis xyz="0 1 0"/>
    <limit effort="100.0" lower="-2.09" upper="2.09" velocity="1.0"/>
    <dynamics damping="0.7" friction="0.9"/>
    <origin rpy="0 0 0" xyz="0 0 0.28"/>
    <default>
      <angle>0.2</angle>
    </default>
  </joint>
  <link name="right_arm_forearm">
    <visual>
      <geometry>
        <mesh filename="package://robot_description/meshes/visual/arm_forearm.dae"/>
      </geometry>
      <material name="body_material"/>
    </visual>
    <collision>
      <geometry>
        <mesh filename="package://robot_description/meshes/collision/arm_forearm.stl"/>
      </geometry>
    </collision>
    <inertial>
      <mass value="1.0"/>
      <inertia ixx="0.01" ixy="0.0" ixz="0.0" iyy="0.01" iyz="0.0" izz="0.01"/>
    </inertial>
  </link>
  <joint name="right_wrist_joint" type="revolute">
    <parent link="right_arm_elbow"/>
    <child link="right_arm_forearm"/>
    <axis xyz="0 1 0"/>
    <limit effort="100.0" lower="-2.09" upper="2.09" velocity="1.0"/>
    <dynamics damping="0.7" friction="0.9"/>
    <origin rpy="0 0 0" xyz="0 0 0.04"/>
    <default>
      <angle>0.0</angle>
    </default>
  </joint>
  <link name="right_arm_wrist">
    <visual>
      <geometry>
        <mesh filename="package://robot_description/meshes/visual/wrist.dae"/>
      </geometry>
      <material name="joint_material"/>
    </visual>
    <collision>
      <geometry>
        <mesh filename="package://robot_description/meshes/collision/wrist.stl"/>
      </geometry>
    </collision>
  </link>
  <joint name="right_wrist_end_joint" type="fixed">
    <parent link="right_arm_forearm"/>
    <child link="right_arm_wrist"/>
    <origin rpy="0 0 0" xyz="0 0 0.26"/>
  </joint>
  <link name="right_hand_palm">
    <visual>
      <geometry>
        <mesh filename="package://robot_description/meshes/visual/hand_palm.dae"/>
      </geometry>
      <material name="joint_material"/>
    </visual>
    <collision>
      <geometry>
        <mesh filename="package://robot_description/meshes/collision/hand_palm.stl"/>
      </geometry>
    </collision>
    <inertial>
      <mass value="0.6"/>
      <inertia ixx="0.0015" ixy="0.0" ixz="0.0" iyy="0.0015" iyz="0.0" izz="0.0015"/>
    </inertial>
  </link>
  <joint name="right_wrist_hand_joint" type="fixed">
    <parent link="right_arm_wrist"/>
    <child link="right_hand_palm"/>
    <origin rpy="0 0 0" xyz="0 0 0"/>
  </joint>
  <link name="left_finger_1">
    <visual>
      <geometry>
        <mesh filename="package://robot_description/meshes/visual/finger.dae"/>
      </geometry>
      <material name="joint_material"/>
    </visual>
    <collision>
      <geometry>
        <mesh filename="package://robot_description/meshes/collision/finger.stl"/>
      </geometry>
    </collision>
    <inertial>
      <mass value="0.1"/>
      <inertia ixx="0.0001" ixy="0.0" ixz="0.0" iyy="0.0001" iyz="0.0" izz="0.0001"/>
    </inertial>
  </link>
  <joint name="left_finger_1_joint" type="revolute">
    <parent link="left_hand_palm"/>
    <child link="left_finger_1"/>
    <axis xyz="0 0 1"/>
    <limit effort="50.0" lower="0.0" upper="1.57" velocity="0.5"/>
    <dynamics damping="0.5" friction="0.7"/>
    <origin rpy="0 0 0" xyz="-0.02 0 -0.025"/>
    <default>
      <angle>0.0</angle>
    </default>
  </joint>
  <link name="left_finger_2">
    <visual>
      <geometry>
        <mesh filename="package://robot_description/meshes/visual/finger.dae"/>
      </geometry>
      <material name="joint_material"/>
    </visual>
    <collision>
      <geometry>
        <mesh filename="package://robot_description/meshes/collision/finger.stl"/>
      </geometry>
    </collision>
    <inertial>
      <mass value="0.1"/>
      <inertia ixx="0.0001" ixy="0.0" ixz="0.0" iyy="0.0001" iyz="0.0" izz="0.0001"/>
    </inertial>
  </link>
  <joint name="left_finger_2_joint" type="revolute">
    <parent link="left_hand_palm"/>
    <child link="left_finger_2"/>
    <axis xyz="0 0 1"/>
    <limit effort="50.0" lower="0.0" upper="1.57" velocity="0.5"/>
    <dynamics damping="0.5" friction="0.7"/>
    <origin rpy="0 0 0" xyz="-0.0067 0 -0.025"/>
    <default>
      <angle>0.0</angle>
    </default>
  </joint>
  <link name="left_finger_3">
    <visual>
      <geometry>
        <mesh filename="package://robot_description/meshes/visual/finger.dae"/>
      </geometry>
      <material name="joint_material"/>
    </visual>
    <collision>
      <geometry>
        <mesh filename="package://robot_description/meshes/collision/finger.stl"/>
      </geometry>
    </collision>
    <inertial>
      <mass value="0.1"/>
      <inertia ixx="0.0001" ixy="0.0" ixz="0.0" iyy="0.0001" iyz="0.0" izz="0.0001"/>
    </inertial>
  </link>
  <joint name="left_finger_3_joint" type="revolute">
    <parent link="left_hand_palm"/>
    <child link="left_finger_3"/>
    <axis xyz="0 0 1"/>
    <limit effort="50.0" lower="0.0" upper="1.57" velocity="0.5"/>
    <dynamics damping="0.5" friction="0.7"/>
    <origin rpy="0 0 0" xyz="0.0067 0 -0.025"/>
    <default>
      <angle>0.0</angle>
    </default>
  </joint>
  <link name="left_finger_4">
    <visual>
      <geometry>
        <mesh filename="package://robot_description/meshes/visual/finger.dae"/>
      </geometry>
      <material name="joint_material"/>
    </visual>
    <collision>
      <geometry>
        <mesh filename="package://robot_description/meshes/collision/finger.stl"/>
      </geometry>
    </collision>
    <inertial>
      <mass value="0.1"/>
      <inertia ixx="0.0001" ixy="0.0" ixz="0.0" iyy="0.0001" iyz="0.0" izz="0.0001"/>
    </inertial>
  </link>
  <joint name="left_finger_4_joint" type="revolute">
    <parent link="left_hand_palm"/>
    <child link="left_finger_4"/>
    <axis xyz="0 0 1"/>
    <limit effort="50.0" lower="0.0" upper="1.57" velocity="0.5"/>
    <dynamics damping="0.5" friction="0.7"/>
    <origin rpy="0 0 0" xyz="0.02 0 -0.025"/>
    <default>
      <angle>0.0</angle>
    </default>
  </joint>
  <!-- Left Leg -->
  <link name="left_leg_hip">
    <visual>
      <geometry>
        <mesh filename="package://robot_description/meshes/visual/hip.dae"/>
      </geometry>
      <material name="joint_material"/>
    </visual>
    <collision>
      <geometry>
        <mesh filename="package://robot_description/meshes/collision/hip.stl"/>
      </geometry>
    </collision>
    <inertial>
      <mass value="1.0"/>
      <inertia ixx="0.01" ixy="0.0" ixz="0.0" iyy="0.01" iyz="0.0" izz="0.01"/>
    </inertial>
  </link>
  <joint name="left_hip_joint" type="revolute">
    <parent link="torso"/>
    <child link="left_leg_hip"/>
    <axis xyz="0 1 0"/>
    <limit effort="100.0" lower="-2.09" upper="2.09" velocity="1.0"/>
    <dynamics damping="0.7" friction="0.9"/>
    <origin rpy="0 0 0" xyz="-0.16 0 0"/>
    <default>
      <angle>0.0</angle>
    </default>
  </joint>
  <link name="left_leg_thigh">
    <visual>
      <geometry>
        <mesh filename="package://robot_description/meshes/visual/thigh.dae"/>
      </geometry>
      <material name="body_material"/>
    </visual>
    <collision>
      <geometry>
        <mesh filename="package://robot_description/meshes/collision/thigh.stl"/>
      </geometry>
    </collision>
    <inertial>
      <mass value="1.5"/>
      <inertia ixx="0.015" ixy="0.0" ixz="0.0" iyy="0.015" iyz="0.0" izz="0.015"/>
    </inertial>
  </link>
  <joint name="left_knee_joint" type="revolute">
    <parent link="left_leg_hip"/>
    <child link="left_leg_thigh"/>
    <axis xyz="0 1 0"/>
    <limit effort="100.0" lower="-2.09" upper="2.09" velocity="1.0"/>
    <dynamics damping="0.7" friction="0.9"/>
    <origin rpy="0 0 0" xyz="0 0 0.04"/>
    <default>
      <angle>0.0</angle>
    </default>
  </joint>
  <link name="left_leg_shin">
    <visual>
      <geometry>
        <mesh filename="package://robot_description/meshes/visual/shin.dae"/>
      </geometry>
      <material name="body_material"/>
    </visual>
    <collision>
      <geometry>
        <mesh filename="package://robot_description/meshes/collision/shin.stl"/>
      </geometry>
    </collision>
    <inertial>
      <mass value="1.2"/>
      <inertia ixx="0.012" ixy="0.0" ixz="0.0" iyy="0.012" iyz="0.0" izz="0.012"/>
    </inertial>
  </link>
  <joint name="left_ankle_joint" type="revolute">
    <parent link="left_leg_thigh"/>
    <child link="left_leg_shin"/>
    <axis xyz="0 1 0"/>
    <limit effort="100.0" lower="-2.09" upper="2.09" velocity="1.0"/>
    <dynamics damping="0.7" friction="0.9"/>
    <origin rpy="0 0 0" xyz="0 0 0.35"/>
    <default>
      <angle>0.0</angle>
    </default>
  </joint>
  <link name="left_leg_ankle">
    <visual>
      <geometry>
        <mesh filename="package://robot_description/meshes/visual/ankle.dae"/>
      </geometry>
      <material name="joint_material"/>
    </visual>
    <collision>
      <geometry>
        <mesh filename="package://robot_description/meshes/collision/ankle.stl"/>
      </geometry>
    </collision>
    <inertial>
      <mass value="0.8"/>
      <inertia ixx="0.008" ixy="0.0" ixz="0.0" iyy="0.008" iyz="0.0" izz="0.008"/>
    </inertial>
  </link>
  <joint name="left_ankle_end_joint" type="fixed">
    <parent link="left_leg_shin"/>
    <child link="left_leg_ankle"/>
    <origin rpy="0 0 0" xyz="0 0 0.32"/>
  </joint>
  <link name="left_foot">
    <visual>
      <geometry>
        <mesh filename="package://robot_description/meshes/visual/foot.dae"/>
      </geometry>
      <material name="body_material"/>
    </visual>
    <collision>
      <geometry>
        <mesh filename="package://robot_description/meshes/collision/foot.stl"/>
      </geometry>
    </collision>
    <inertial>
      <mass value="1.5"/>
      <inertia ixx="0.015" ixy="0.0" ixz="0.0" iyy="0.015" iyz="0.0" izz="0.015"/>
    </inertial>
  </link>
  <joint name="left_ankle_foot_joint" type="fixed">
    <parent link="left_leg_ankle"/>
    <child link="left_foot"/>
    <origin rpy="0 0 0" xyz="0 0 -0.045"/>
  </joint>
  <!-- Right Leg (Mirrored) -->
  <link name="right_leg_hip">
    <visual>
      <geometry>
        <mesh filename="package://robot_description/meshes/visual/hip.dae"/>
      </geometry>
      <material name="joint_material"/>
    </visual>
    <collision>
      <geometry>
        <mesh filename="package://robot_description/meshes/collision/hip.stl"/>
      </geometry>
    </collision>
    <inertial>
      <mass value="1.0"/>
      <inertia ixx="0.01" ixy="0.0" ixz="0.0" iyy="0.01" iyz="0.0" izz="0.01"/>
    </inertial>
  </link>
  <joint name="right_hip_joint" type="revolute">
    <parent link="torso"/>
    <child link="right_leg_hip"/>
    <axis xyz="0 1 0"/>
    <limit effort="100.0" lower="-2.09" upper="2.09" velocity="1.0"/>
    <dynamics damping="0.7" friction="0.9"/>
    <origin rpy="0 0 0" xyz="0.16 0 0"/>
    <default>
      <angle>0.0</angle>
    </default>
  </joint>
  <link name="right_leg_thigh">
    <visual>
      <geometry>
        <mesh filename="package://robot_description/meshes/visual/thigh.dae"/>
      </geometry>
      <material name="body_material"/>
    </visual>
    <collision>
      <geometry>
        <mesh filename="package://robot_description/meshes/collision/thigh.stl"/>
      </geometry>
    </collision>
    <inertial>
      <mass value="1.5"/>
      <inertia ixx="0.015" ixy="0.0" ixz="0.0" iyy="0.015" iyz="0.0" izz="0.015"/>
    </inertial>
  </link>
  <joint name="right_knee_joint" type="revolute">
    <parent link="right_leg_hip"/>
    <child link="right_leg_thigh"/>
    <axis xyz="0 1 0"/>
    <limit effort="100.0" lower="-2.09" upper="2.09" velocity="1.0"/>
    <dynamics damping="0.7" friction="0.9"/>
    <origin rpy="0 0 0" xyz="0 0 0.04"/>
    <default>
      <angle>0.0</angle>
    </default>
  </joint>
  <link name="right_leg_shin">
    <visual>
      <geometry>
        <mesh filename="package://robot_description/meshes/visual/shin.dae"/>
      </geometry>
      <material name="body_material"/>
    </visual>
    <collision>
      <geometry>
        <mesh filename="package://robot_description/meshes/collision/shin.stl"/>
      </geometry>
    </collision>
    <inertial>
      <mass value="1.2"/>
      <inertia ixx="0.012" ixy="0.0" ixz="0.0" iyy="0.012" iyz="0.0" izz="0.012"/>
    </inertial>
  </link>
  <joint name="right_ankle_joint" type="revolute">
    <parent link="right_leg_thigh"/>
    <child link="right_leg_shin"/>
    <axis xyz="0 1 0"/>
    <limit effort="100.0" lower="-2.09" upper="2.09" velocity="1.0"/>
    <dynamics damping="0.7" friction="0.9"/>
    <origin rpy="0 0 0" xyz="0 0 0.35"/>
    <default>
      <angle>0.0</angle>
    </default>
  </joint>
  <link name="right_leg_ankle">
    <visual>
      <geometry>
        <mesh filename="package://robot_description/meshes/visual/ankle.dae"/>
      </geometry>
      <material name="joint_material"/>
    </visual>
    <collision>
      <geometry>
        <mesh filename="package://robot_description/meshes/collision/ankle.stl"/>
      </geometry>
    </collision>
    <inertial>
      <mass value="0.8"/>
      <inertia ixx="0.008" ixy="0.0" ixz="0.0" iyy="0.008" iyz="0.0" izz="0.008"/>
    </inertial>
  </link>
  <joint name="right_ankle_end_joint" type="fixed">
    <parent link="right_leg_shin"/>
    <child link="right_leg_ankle"/>
    <origin rpy="0 0 0" xyz="0 0 0.32"/>
  </joint>
  <link name="right_foot">
    <visual>
      <geometry>
        <mesh filename="package://robot_description/meshes/visual/foot.dae"/>
      </geometry>
      <material name="body_material"/>
    </visual>
    <collision>
      <geometry>
        <mesh filename="package://robot_description/meshes/collision/foot.stl"/>
      </geometry>
    </collision>
    <inertial>
      <mass value="1.5"/>
      <inertia ixx="0.015" ixy="0.0" ixz="0.0" iyy="0.015" iyz="0.0" izz="0.015"/>
    </inertial>
  </link>
  <joint name="right_ankle_foot_joint" type="fixed">
    <parent link="right_leg_ankle"/>
    <child link="right_foot"/>
    <origin rpy="0 0 0" xyz="0 0 -0.045"/>
  </joint>
  <!-- Gazebo Configuration -->
  <gazebo>
    <plugin filename="libgazebo_ros_control.so" name="gazebo_ros_control">
      <robotNamespace>/cori</robotNamespace>
      <controlPeriod>0.001</controlPeriod>
      <joint>
        <name>neck_joint</name>
        <type>position</type>
      </joint>
      <joint>
        <name>waist_joint</name>
        <type>position</type>
      </joint>
      <joint>
        <name>left_shoulder_joint</name>
        <type>position</type>
      </joint>
      <joint>
        <name>left_elbow_joint</name>
        <type>position</type>
      </joint>
      <joint>
        <name>left_wrist_joint</name>
        <type>position</type>
      </joint>
      <joint>
        <name>left_finger_1_joint</name>
        <type>position</type>
      </joint>
      <joint>
        <name>left_finger_2_joint</name>
        <type>position</type>
      </joint>
      <joint>
        <name>left_finger_3_joint</name>
        <type>position</type>
      </joint>
      <joint>
        <name>left_finger_4_joint</name>
        <type>position</type>
      </joint>
      <joint>
        <name>right_shoulder_joint</name>
        <type>position</type>
      </joint>
      <joint>
        <name>right_elbow_joint</name>
        <type>position</type>
      </joint>
      <joint>
        <name>right_wrist_joint</name>
        <type>position</type>
      </joint>
      <joint>
        <name>right_finger_1_joint</name>
        <type>position</type>
      </joint>
      <joint>
        <name>right_finger_2_joint</name>
        <type>position</type>
      </joint>
      <joint>
        <name>right_finger_3_joint</name>
        <type>position</type>
      </joint>
      <joint>
        <name>right_finger_4_joint</name>
        <type>position</type>
      </joint>
      <joint>
        <name>left_hip_joint</name>
        <type>position</type>
      </joint>
      <joint>
        <name>left_knee_joint</name>
        <type>position</type>
      </joint>
      <joint>
        <name>left_ankle_joint</name>
        <type>position</type>
      </joint>
      <joint>
        <name>right_hip_joint</name>
        <type>position</type>
      </joint>
      <joint>
        <name>right_knee_joint</name>
        <type>position</type>
      </joint>
      <joint>
        <name>right_ankle_joint</name>
        <type>position</type>
      </joint>
    </plugin>
    <selfCollide>true</selfCollide>
  </gazebo>
  <!-- ROS2 Integration -->
  <transmission name="neck_trans">
    <type>transmission_interface/SimpleTransmission</type>
    <joint name="neck_joint">
      <hardwareInterface>hardware_interface/PositionJointInterface</hardwareInterface>
    </joint>
    <actuator name="neck_motor">
      <mechanicalReduction>1</mechanicalReduction>
    </actuator>
  </transmission>
  <!-- Add similar transmissions for all joints as needed -->
</robot>
